Workbook

Sheet 00_README
A1: Longevity Master OS v2 | K1: Created | L1: 2026-05-15 11:11 PM CT
A2: Read this once. Bookmark 02_Brief_Today on your phone.
A5: NAVIGATION
A6: Level 1 — Brief (what to do NOW) | B6: → 02_Brief_Today
A7: Level 2 — Guided (steps + how to know it is right) | B7: → 03_Guided_Steps
A8: Level 3 — Deep (why, when, how, sources) | B8: → 04_Deep_Protocol
A9: 30-day onboarding rotation | B9: → 05_30Day_Rotation
A10: Weekly training pattern | B10: → 06_Weekly_Plan
A11: Exercise library (moves, sets, videos) | B11: → 07_Exercise_Library
A12: Nutrition system | B12: → 08_Nutrition
A13: Supplements (Category + Status + Stop rule) | B13: → 09_Supplements
A14: Blood biomarker panel | B14: → 10_Blood_Markers
A15: Screening, vaccines, emergency red flags | B15: → 11_Screenings_Safety
A16: Sleep + heat/cold recovery | B16: → 12_Sleep_Recovery
A17: Cognitive + social health | B17: → 13_Cognitive_Social
... A19: Source citations (CDC / USPSTF / AHA / research) | B19: → 15_Sources
A21: FIRST-TIME SETUP
A22: Step 1 | B22: Open 01_Personal_Settings. Fill the blue cells (name, DOB, sex, height, weight, RHR, VO2, grip). Everything else flows from these.
A23: Step 2 | B23: Open 02_Brief_Today. You should see your name and live protein/hydration targets at the top.
A24: Step 3 | B24: Open 11_Screenings_Safety. Enter last-done dates for screenings you have had. Next-due dates auto-calculate.
A25: Step 4 | B25: Book your baseline labs (10_Blood_Markers shows what to ask for). Bring the markers list to your physician.
A26: Step 5 | B26: Until labs are back, follow Category B supplements only (creatine, omega-3, psyllium). See 09_Supplements.
A28: COLOR CONVENTIONS (financial-model standard)
A29: Blue text | B29: Your input — change these
A30: Black text | B30: Formula — auto-calculated
A31: Green text | B31: Cross-sheet link — pulls from another tab
A32: Yellow fill | B32: Needs attention or due now
A33: Green fill | B33: In optimal/target range
A34: Red fill | B34: Out of range or red-flag item
A36: MEDICAL DISCLAIMER
B37: This is an educational planning workbook to help structure conversations with your physician. It is not medical diagnosis or treatment. All supplement, training, and lab decisions for a 60+ year old should be reviewed with a clinician — especially before starting anything new, changing prescription medications, or interpreting blood markers. The "longevity-optimal" target ranges shown are tighter than standard population norms (sourced from peer-reviewed longevity literature) and represent goals to discuss with your physician, not clinical decision thresholds.
A39: THREE-LEVEL DETAIL — HOW TO USE
A40: Daily | B40: Open 02_Brief_Today on your phone. Tap through the time-blocked actions.
A41: Weekly | B41: Sunday: glance at 06_Weekly_Plan to log compliance.
A42: When learning a new move | B42: Click into 07_Exercise_Library for cues, sets/reps, video search.
A43: When you want to understand why | B43: Open 04_Deep_Protocol. Each row has the mechanism, source, and owner (self/clinician/trainer).
A44: Quarterly | B44: Re-enter blood markers in 10_Blood_Markers. Auto-status updates supplement decisions in 09_Supplements.

Sheet 01_Personal_Settings
A1: Personal Settings | K1: Created | L1: 2026-05-15 11:11 PM CT
A2: Single source of truth. Change a blue cell and the entire workbook updates.
A5: INPUTS (blue cells — change these)
A6: Name | B6: Pankaj Kumar | C6: Used in greetings
A7: Date of birth | B7: 24108 | C7: YYYY-MM-DD format
A8: Sex at birth | B8: M | C8: M or F (affects screening defaults)
A9: Height (cm) | B9: 155 | C9: For BMI
A10: Weight (kg) | B10: 59 | C10: Drives protein, hydration targets
A11: Resting heart rate | B11: 61 | C11: Beats/min, measured first thing in morning
A12: Current VO2 max (mL/kg/min) | B12: 35 | C12: From Garmin/Apple Watch or treadmill test
A13: Grip strength (kg) | B13: 35 | C13: Strongest hand, hand dynamometer
A14: DERIVED (black/green — auto-calculated)
A15: Today | B15: =TODAY() -> 46157 | C15: m/d/yyyy
A16: Age (years) | B16: =INT((B15-B7)/365.25) -> 60 | C16: Auto from DOB
A17: BMI | B17: =B10/((B9/100)^2) -> 24.557752 | C17: Height(m)² / weight
A18: BMI category | B18: =IF(B17<18.5,"Underweight",IF(B17<25,"Normal",IF(B17<30,"Overweight","Obese"))) -> Normal
A19: Protein target (g/day) | B19: =ROUND(B10*1.6,0) -> 94 | C19: 1.6 g/kg — active aging (Bauer PROT-AGE upper)
A20: Per-meal protein (g) | B20: =ROUND(B19/4,0) -> 24 | C20: Hit leucine threshold (2.5g) each meal
A21: Hydration target (L/day) | B21: =ROUND(B10*30/1000,1) -> 1.8 | C21: 30 mL/kg/day
A22: Max heart rate (bpm) | B22: =ROUND(208-0.7*B16,0) -> 166 | C22: Tanaka 2001 formula
A23: Zone 2 HR target (bpm) | B23: =ROUND(B22*0.7,0) -> 116 | C23: 70% maxHR — conversational pace
A24: VO2 interval HR (bpm) | B24: =ROUND(B22*0.9,0) -> 149 | C24: 90% maxHR — Norwegian 4×4 protocol
A25: Today (display) | B25: =TEXT(B15,"dddd, mmmm d, yyyy") -> Friday, May 15, 2026

Sheet 02_Brief_Today
A1: Brief — Today | K1: Created | L1: 2026-05-15 11:11 PM CT
A2: Fast operating checklist. Priority now: upper-back strength + core bracing first, then legs/push/cardio. Week 1 is intentionally easy; Week 2 adds a small progression.
A4: Time | B4: Do now | C4: Duration | D4: Week 1 dosage | E4: Week 2 progression | F4: Why | G4: Done? | H4: Notes | I4: Source key | J4: Link
A5: 05:30 | B5: Wake, water, bathroom. Optional: BP/weight if tracking. | C5: 10 min | D5: Easy; no rushing | E5: Same | F5: Consistent wake time anchors circadian rhythm and makes training repeatable. | G5: ☐ | I5: CDC-SLEEP
A6: 05:40 | B6: Warm-up before any training: nasal breathing walk + joint circles + cat-cow + band pull-aparts. | C6: 8–10 min | D6: RPE 2–3 | E6: RPE 3–4 | F6: Raises tissue temperature, rehearses posture, lowers injury risk before loading. | G6: ☐ | I6: CDC-ACT
A7: 05:50 | B7: Priority strength block: upper back + core first. | C7: 15–25 min | D7: 2 rounds, easy, RPE 5–6 | E7: 3 rounds or +1 set, RPE 6–7 | F7: Upper back supports shoulder mechanics and posture; core bracing protects the spine before lower-body loading. | G7: ☐ | I7: NIA-STRENGTH
A8: 06:15 | B8: Secondary body block: legs/push/carry or Zone 2 depending on daily plan. | C8: 10–25 min | D8: Technique only | E8: Add small volume/load | F8: Build whole-body capacity without letting early fatigue ruin posture/core quality. | G8: ☐ | I8: CDC-ACT
A9: 06:40 | B9: Cool-down: slow walk, long exhale breathing, thoracic/hip stretch. | C9: 5–10 min | D9: RPE 1–2 | E9: Same | F9: Downshifts the nervous system and reduces stiffness after training. | G9: ☐ | I9: CDC-ACT
A10: 07:00 | B10: Protein-forward breakfast + fiber + colorful plants. | C10: 20 min | D10: Hit per-meal protein target | E10: Same | F10: Supports muscle protein synthesis and satiety in older adults. | G10: ☐ | I10: PROT-AGE
A11: 12:30 | B11: Lunch: protein + vegetables + legumes/whole grain + olive oil. | C11: 25 min | D11: Half plate plants | E11: Same | F11: Mediterranean pattern supports cardiometabolic health. | G11: ☐ | I11: DGA-2025
A12: 14:00 | B12: 10–15 min walk after lunch. | C12: 10–15 min | D12: Easy | E12: Same or +5 min | F12: Post-meal movement improves glucose handling and adds low-stress volume. | G12: ☐ | I12: CDC-ACT
A13: 17:00 | B13: Optional recovery: easy walk, mobility, or sauna if medically appropriate. | C13: 15–30 min | D13: Easy only | E13: Same | F13: Recovery tools should support—not compete with—training adaptation. | G13: ☐ | I13: CDC-ACT
A14: 19:00 | B14: Dinner: protein + vegetables; keep it light and earlier. | C14: 30 min | D14: No heavy late meal | E14: Same | F14: Helps sleep quality and glucose control. | G14: ☐ | I14: DGA-2025
A15: 20:30 | B15: Sleep wind-down: dim light, screens down, breathing/journal/read. | C15: 30–60 min | D15: Consistent | E15: Consistent | F15: Sleep consolidates recovery, learning, glucose regulation, and pain sensitivity. | G15: ☐ | I15: CDC-SLEEP
A16: 22:00 | B16: Lights out. Protect 7–9 hr sleep opportunity. | C16: 7–9 hr | D16: Target consistency | E16: Target consistency | F16: Sleep is the recovery multiplier. | G16: ☐ | I16: CDC-SLEEP
A18: THIS WEEK — NON-NEGOTIABLE MINIMUMS
A19: Pillar | B19: Minimum | C19: Week 1 | D19: Week 2 | E19: Track | F19: Notes | I19: Source key | J19: Link
A20: Upper back | B20: 3 sessions/week | C20: Band row + face pull + wall slide | D20: +1 set or stronger band | E20: Sessions | F20: Start every strength day here. | I20: NIA-STRENGTH
A21: Core/bracing | B21: 3 sessions/week | C21: Dead bug + bird dog + side plank | D21: +5–10 sec holds or +1 set | E21: Sessions | F21: Avoid sit-ups if back pain. | I21: NIA-STRENGTH
A22: Lower body | B22: 2 sessions/week | C22: Sit-to-stand + glute bridge | D22: Add goblet squat or step-up | E22: Sessions | F22: Only after warm-up and core activation. | I22: CDC-ACT
A23: Aerobic | B23: 150 min/week moderate | C23: Walk/cycle easy Zone 2 | D23: +10–15 min total/week | E23: Minutes | F23: Can be broken into short bouts. | I23: CDC-ACT
A24: Balance | B24: Daily 3–5 min | C24: Tandem stance, supported single-leg | D24: +10–20 sec total | E24: Days | F24: Safety support nearby. | I24: USPSTF-FALLS
A25: Warm-up + cool-down | B25: Every session | C25: 8–10 min warm-up; 5–10 min cool-down | D25: Same | E25: Yes/No | F25: Do not skip. | I25: CDC-ACT
A27: 🚨 RED FLAGS — stop training and seek urgent care/clinician guidance
A28: Chest pain, fainting, sudden severe shortness of breath, stroke symptoms, severe new joint pain, sudden weakness/numbness, or pain that changes gait. For new exercise at 60+, review major medical risks with your clinician.

Sheet 03_Guided_Steps
A1: Guided Routine — Steps + How to Know It Is Right | K1: Created | L1: 2026-05-15 11:11 PM CT
A2: Enough detail to finish the job without reading the full science. Each row links to 04_Deep_Protocol for the why.
A4: Block | B4: When | C4: Steps to complete | D4: Dose / target | E4: How to know it is right | F4: Why it matters | G4: Deep detail → | H4: Source key | I4: Safety / modification | J4: Owner
A5: Morning activation | B5: After waking | C5: Water · bathroom · 5–15 min outdoor light · 5 slow nasal breaths · BP/weight if tracking | D5: Daily | E5: Awake but calm; HR settles within 10 min | F5: Anchors circadian rhythm and morning health-data habit | G5: Sleep + morning light | H5: CDC-SLEEP | I5: Sit first if dizzy; clinician if recurrent | J5: Self
A6: Mobility primer | B6: Before training | C6: Ankle rocks · hip hinge practice · thoracic rotations · shoulder circles · tandem walk | D6: 8–12 min daily | E6: Warm joints; pain ≤3/10 | F6: Prepares joints, reduces injury risk | G6: Moves | H6: CDC-ACT | I6: Reduce range if painful | J6: Self / Trainer
A7: Strength day | B7: Mon/Wed/Fri | C7: Warm up · squat/hinge/push/pull/carry/core · 2–3 sets each, progressive load | D7: 30–45 min · 2–3×/wk | E7: Challenging controlled reps; soreness 1–2 days then resolves | F7: Preserves muscle, bone, glucose control, independence | G7: Strength library | H7: CDC-ACT · ATTIA-4P | I7: Avoid breath-holding (Valsalva); coach if new | J7: Trainer
A8: Zone 2 day | B8: Tue/Thu/Sat | C8: Brisk walk / bike / swim / elliptical at conversational pace | D8: =30&"–60 min · HR ~"&'01_Personal_Settings'!B23&" bpm" -> 30–60 min · HR ~116 bpm | E8: Can speak full sentences, not sing | F8: Builds aerobic base + mitochondrial density | G8: Zone 2 | H8: CDC-ACT · ATTIA-4P | I8: Use bike/swim for joint pain; stop if chest pain | J8: Self
A9: VO2 max intervals | B9: 1× per week | C9: After 10-min warmup: 4×4 min near-max effort with 3 min easy recovery | D9: =30&" min total · interval HR "&'01_Personal_Settings'!B24&" bpm" -> 30 min total · interval HR 149 bpm | E9: Hard but completable; ~RPE 8–9 | F9: Strongest mortality predictor in cardio domain | G9: Zone 2 + VO2 | H9: WISLOFF-2007 · MANDSAGER-2018 | I9: Cardio clearance if heart risk; stop if chest pain | J9: Trainer / Clinician
A10: Balance focus | B10: Daily micro + 2 focused days | C10: Tandem stance/walk · sit-to-stand · single-leg support near counter · heel raises | D10: 5–10 min daily | E10: Challenged but safe; gradually less hand support | F10: Reduces fall risk by ~25% | G10: Balance | H10: CDC-ACT | I10: Use support; avoid eyes-closed work unsupervised | J10: PT / Self
A11: Breakfast | B11: After training | C11: Protein + fiber-carb + colorful plant + healthy fat | D11: =ROUND('01_Personal_Settings'!B20,0)&" g protein" -> 24 g protein | E11: Energy stable until lunch | F11: Protein distribution supports muscle protein synthesis | G11: Breakfast builder | H11: PROT-AGE · DGA-2025 | I11: Personalize for diabetes/kidney disease | J11: Self / Dietitian
A12: Lunch + walk | B12: Midday | C12: Protein bowl: vegetables, legumes/whole grain, olive oil/nuts · 10-min walk after | D12: =ROUND('01_Personal_Settings'!B20,0)&" g protein + 10 min walk" -> 24 g protein + 10 min walk | E12: No afternoon crash | F12: Mediterranean pattern + post-prandial movement = best cardiometabolic | G12: Lunch builder | H12: DGA-2025 | I12: Smaller meal if reflux | J12: Self
A13: Supplements / meds | B13: With meals as prescribed | C13: Only items with reason · dose · start date · interaction check · stop rule | D13: Monthly review | E13: Every item has stated purpose; no orphan bottles | F13: Avoids unsafe stacking, drug interactions, hidden harm | G13: Supplements | H13: NIH-ODS | I13: No iron/hormones/aspirin/off-label unless prescribed | J13: Clinician / Pharmacist
A14: Brain + social | B14: Afternoon | C14: Learning block + social touchpoint: reading, language, music, mentoring, call | D14: 30–60 min | E14: Calendar item completed | F14: Builds cognitive reserve, mood, longevity (Lancet 2024) | G14: Brain/social | H14: NIA-COG · LANCET-2024 | I14: Treat depression / isolation early | J14: Self / Family
A15: Sauna (heat) | B15: 4×/wk recommended | C15: Dry sauna 80°C (175°F), 20+ min, hydrate before | D15: 20–30 min | E15: Adapted; HR ~120, not dizzy | F15: 50% lower CV death, 40% lower all-cause death (Laukkanen 2015) | G15: Heat protocol | H15: LAUKKANEN-2015 | I15: Stop if dizzy; not for unstable angina, severe AS | J15: Self / Clinician
A16: Dinner | B16: Early evening | C16: Protein + vegetables · stop heavy meal 2–3 hr before bed | D16: =ROUND('01_Personal_Settings'!B20,0)&" g protein" -> 24 g protein | E16: Sleep not disturbed | F16: Supports recovery, glucose, reflux, sleep | G16: Dinner builder | H16: DGA-2025 · CDC-SLEEP | I16: Avoid alcohol as sleep aid | J16: Self
A17: Sleep shutdown | B17: 60 min before bed | C17: Dim lights · screens off / blue blockers · gratitude · breathing · cool/dark/quiet room | D17: ≥7 hr sleep opportunity | E17: Wake rested without alarm > alarm | F17: Sleep is foundational for heart, brain, immune, hormonal health | G17: Sleep protocol | H17: CDC-SLEEP · WALKER-2017 | I17: Evaluate apnea symptoms (snoring + daytime sleepiness) | J17: Self / Clinician
A18: Weekly review | B18: Sunday | C18: Review compliance, pain, sleep, BP/weight, next appointments, groceries, training load | D18: 20–30 min | E18: Next week scheduled, deload decision made | F18: Creates closed-loop behavior system | G18: Dashboard | H18: AHA-LE8 | I18: Deload if pain or fatigue persist | J18: Self

Sheet 04_Deep_Protocol
A1: Deep Protocol — Why, When, How, Sources | K1: Created | L1: 2026-05-15 11:11 PM CT
A2: Science-backed operating manual. Each row: mechanism, evidence, measurement, owner. Click Source key → 15_Sources for citation.
A4: Protocol | B4: Pillar | C4: When | D4: Exact method | E4: Progression / target | F4: Mechanism (why it works) | G4: Measurement | H4: Red flags / clinician notes | I4: Source key | J4: Owner
A5: Sleep + circadian | B5: Foundation | C5: Daily | D5: Consistent wake (±30 min). Outdoor light <30 min after waking. Dim lights 60 min before bed. Bedroom 18°C (65°F), dark, quiet. Warm shower 1–2 hr pre-bed (Liao 2025 footbath meta-analysis). | E5: Build to ≥7 hr nightly average; sleep efficiency >85% | F5: Light at eye anchors SCN master clock; cool environment + warm-extremity vasodilation → core temp drop → sleep onset. Sleep regularity outranks duration for cardio outcomes. | G5: Hours slept, sleep regularity, daytime energy, snoring (apnea screen) | H5: Snoring + daytime sleepiness → sleep apnea evaluation (STOP-BANG, polysomnography). Insomnia >3 mo → CBT-I (first-line per AASM). | I5: CDC-SLEEP · WALKER-2017 · LIAO-2025 | J5: Self / Clinician
A6: Aerobic base — Zone 2 | B6: Cardiorespiratory | C6: Tue/Thu/Sat | D6: Walk / bike / swim / row at conversational pace. HR ~70% maxHR (formula: 208 − 0.7×age × 0.7). RPE 4–5. Nasal breathing if possible. | E6: Build to 150–300 min/wk moderate (CDC) or 3–4 × 45–60 min | F6: Increases mitochondrial density, fat oxidation, capillary density. Plateau in adaptations after ~3 months without volume increase. | G6: Minutes/week, RPE, HR drift over time (improving fitness lowers HR at same pace) | H6: Chest pain, fainting, neuro signs → urgent care. New AFib symptoms (palpitations) → cardiology. | I6: CDC-ACT · ATTIA-4P · SAN-MILLAN-2018 | J6: Self / Trainer
A7: VO2 max — Norwegian 4×4 | B7: Cardiorespiratory | C7: 1×/week | D7: 10 min warmup → 4 × (4 min @ 85–95% maxHR, 3 min easy recovery) → 5 min cool down. Total ~30 min. Hard. Use bike for joint safety. | E7: Track VO2 estimate quarterly; goal: ≥90th percentile for age | F7: VO2 max is the strongest single mortality predictor in healthy adults (Mandsager 2018, JAMA Netw Open). Norwegian protocol proven to raise VO2 max ~10% in 8 weeks (Wisloff 2007). | G7: VO2 estimate (Garmin/Apple), 1-mile or 6-min walk test | H7: Requires cardio clearance if HTN, CAD, AFib, or sedentary. Stop immediately for chest pain. | I7: WISLOFF-2007 · MANDSAGER-2018 · ATTIA-4P | J7: Trainer / Clinician
A8: Strength — 6 patterns | B8: Musculoskeletal | C8: Mon/Wed/Fri | D8: Squat (sit-to-stand → goblet squat) · hinge (kettlebell deadlift, RDL) · push (incline → bench → overhead) · pull (band row, lat pulldown) · carry (farmer carry) · core (dead bug, plank). 2–3 sets × 6–12 reps, progressive load. | E8: Progress load 2.5–5% when all sets at top rep range with clean form | F8: Sarcopenia begins ~age 30, accelerates ~age 60 (~1–2% muscle/yr lost without training). Strength training reverses this; preserves bone, glucose handling, balance, independence. | G8: Loads × reps log, sit-to-stand test (chair stand count in 30 sec) | H8: Avoid Valsalva (breath-holding) with high BP. Get coaching if new. Stop if sharp joint pain. | I8: CDC-ACT · ATTIA-4P · FIATARONE-1994 | J8: Trainer
A9: Grip strength | B9: Musculoskeletal | C9: 2×/wk add-on | D9: Farmer carry (heaviest weights you can hold × 30–60 sec walks), dead hangs (build to 30+ sec), towel pull-ups, hand dynamometer monthly. | E9: Grip ≥40 kg (men), ≥27 kg (women) — inversely correlates with mortality | F9: PURE study (Leong 2015, Lancet) — each 5 kg drop in grip = 16% higher mortality. Proxies whole-body strength and CNS integrity. | G9: Hand dynamometer (best of 3 trials, both hands) | H9: Joint pain → rotate to neutral-grip carries. | I9: LEONG-2015 · ATTIA-4P | J9: Trainer / Self
A10: Balance / fall prevention | B10: Musculoskeletal | C10: Daily micro + 2 focused | D10: Tandem stance/walk · single-leg support near counter · sit-to-stand · step-ups · heel raises · eyes-closed near support. Progress: less hand support. | E10: Hold single-leg ≥30 sec each side; 30-sec chair stand ≥15 reps | F10: Falls = leading cause of injury death in adults 65+ (CDC). Training cuts falls ~25% (Cochrane 2019). | G10: Single-leg balance time, fall events | H10: After any fall: PT eval, vision check, medication review (especially benzos, antihypertensives). | I10: CDC-ACT · COCHRANE-2019 | J10: PT / Self
A11: Mobility / pain prevention | B11: Musculoskeletal | C11: Daily | D11: Ankle dorsiflexion (knee-to-wall) · hip flexor stretch · thoracic rotations · shoulder CARs (controlled articular rotations). Gentle loaded mobility, not just stretching. | E11: Maintain functional ranges; intervene with PT if pain >2 weeks | F11: Tissue tolerance is trainable. Loss of joint range = #1 modifiable risk for training injury. | G11: Pain 0–10 scale, stiffness diary, functional ranges (e.g., overhead reach) | H11: Sharp / night / neuropathic pain → clinical evaluation. | I11: CDC-ACT | J11: PT / Trainer
A12: Nutrition pattern | B12: Nutrition | C12: Every meal | D12: Mediterranean-style plate: protein (palm-size) + 2 fistfuls vegetables + 1 cupped legume/whole grain + thumb healthy fat. Olive oil base. Limit added sugar, ultra-processed, sodium >2300 mg/day. | E12: Whole-food meals ≥80% of intake. Adjust calories to weight goal. | F12: Mediterranean diet reduces cardiac events ~30% (PREDIMED 2018 NEJM re-analysis), improves cognition (Reynolds 2019 Lancet review). | G12: Body comp (weight, waist), labs (lipids, A1c, ApoB) | H12: Personalize for diabetes, CKD, GI disease, food allergies. Dietitian for complex cases. | I12: DGA-2025 · PREDIMED-2018 · REYNOLDS-2019 | J12: Self / Dietitian
A13: Protein for sarcopenia | B13: Nutrition | C13: 3–4 meals/day | D13: 1.6 g/kg/day for active 60+ (Bauer PROT-AGE upper range). Distribute evenly. Each meal must hit ~2.5 g leucine threshold (= 25–40 g high-quality protein). | E13: ="Daily total: "&'01_Personal_Settings'!B19&" g; per meal: "&'01_Personal_Settings'!B20&" g" -> Daily total: 94 g; per meal: 24 g | F13: Anabolic resistance increases with age — older adults need more protein per meal to trigger muscle protein synthesis (MPS) than young adults. Leucine is the trigger amino acid. | G13: Daily protein log, body composition trend | H13: Kidney disease (eGFR <60) requires nephrologist plan — usually 0.6–0.8 g/kg. | I13: PROT-AGE · MORTON-2018 · MITCHELL-2017 | J13: Self / Dietitian
A14: Hydration | B14: Nutrition | C14: Daily | D14: 30 mL/kg/day baseline (your weight × 30). More with sauna or training. Front-load morning, slow PM. | E14: ="Target: "&'01_Personal_Settings'!B21&" L/day" -> Target: 1.8 L/day | F14: Dehydration worsens BP swings, constipation, kidney stones, cognition. | G14: Urine color (pale straw = adequate) | H14: Heart failure or kidney disease → clinician-set fluid limit overrides this. | I14: NAM-2005 | J14: Self / Clinician
A15: Supplements decision | B15: Nutrition | C15: Quarterly review | D15: Category A (replacement — take only if labs show deficient): D3, B12, iron, CoQ10 (statin), multivitamin. Category B (therapeutic — take regardless): creatine 5g, omega-3 2g, psyllium 5–10g. Category C (optional/cycle): magnesium glycinate, ashwagandha (cycle). | E15: Adjust at each blood panel (90-day cycles) | F15: Supplements work via two different mechanisms. Replacement supplements only help if you are deficient. Therapeutic supplements create a pharmacological effect regardless of blood level. | G15: Blood markers (see 10_Blood_Markers) | H15: Iron only if ferritin low. Aspirin not routine prevention >60 (USPSTF 2022). No hormones / rapamycin / metformin off-label without specialist. | I15: NIH-ODS · USPSTF-ASPIRIN | J15: Self / Clinician / Pharmacist
A16: Heat — sauna | B16: Recovery | C16: 4–7×/wk | D16: Dry sauna 80°C (175°F) × 20+ min, post-training. Hydrate before. Cool down passively. | E16: Build to 4×/wk minimum; 7×/wk shows dose-response | F16: Laukkanen 2015 (JAMA Intern Med) — Finnish cohort n=2315, 20 yr: 4–7×/wk vs 1×/wk = 50% lower CV death, 40% lower all-cause death. Heat shock proteins, endothelial function, cardiovascular conditioning similar to moderate exercise. | G16: Sessions/week, HR during, perceived adaptation | H16: Not for unstable angina, severe aortic stenosis. Avoid alcohol before. Pregnancy: contraindicated. | I16: LAUKKANEN-2015 | J16: Self / Clinician
A17: Cold exposure | B17: Recovery | C17: 11 min/wk total | D17: Cold water ≤15°C (60°F): 2–3 sessions × 2–4 min OR 1 long session. Soberg 2021 protocol. | E17: 11 min/wk total cold time | F17: Brown fat activation, norepinephrine 200–500%, mood elevation. Soberg 2021 (Cell Reports Medicine) showed metabolic benefits at this dose. | G17: Subjective mood, frequency | H17: Not for severe cardiovascular disease, Raynaud's, cold urticaria. Never alone. | I17: SOBERG-2021 | J17: Self / Clinician
A18: Cardiovascular risk | B18: Prevention | C18: Monthly BP, annual labs | D18: Home BP (best of 3, AM/PM), lipid panel + ApoB + Lp(a) once, A1c, hs-CRP. Treat per ACC/AHA risk calculator + shared decision. | E18: Targets discussed with clinician; longevity-optimal ranges in 10_Blood_Markers | F18: Atherosclerosis is the #1 killer. ApoB is the single best lipid marker (Marston 2022 JAMA Cardiology). Early aggressive management = decades of preserved healthspan. | G18: BP, ApoB, LDL-C, A1c, weight, waist | H18: Statin discussion if ASCVD risk >7.5%. Lp(a) elevated = different risk pathway. | I18: AHA-LE8 · MARSTON-2022 · USPSTF-LIPIDS | J18: Primary Care / Cardiology
A19: Cancer screening | B19: Prevention | C19: Age/risk-based | D19: Colonoscopy q10y age 45–75 (or stool DNA q3y). Skin check annually (or by derm). LDCT lung if 50–80 + smoking criteria. Mammogram q1–2y if F. PSA shared decision 55–69 if M. Skin / oral / pelvic by clinician. | E19: Document last/next dates in 11_Screenings_Safety | F19: USPSTF and ACS evidence-based recommendations. Catching cancer at stage 1 vs stage 3 = ~3–10× higher survival. | G19: Dates done, results | H19: Family history (Lynch, BRCA) requires earlier/different screening — genetics consult. | I19: USPSTF-CRC · USPSTF-LUNG · USPSTF-PSA · USPSTF-SKIN | J19: Primary Care
A20: Vaccines | B20: Prevention | C20: Annual + age-based | D20: Flu (annual), COVID (current schedule), shingles (Shingrix ×2 if ≥50), pneumococcal (PCV20 ≥65), Td/Tdap (q10y), RSV (≥75 or risk), travel as indicated. | E20: CDC adult schedule current year | F20: Vaccines prevent acute illness AND reduce dementia risk (shingles vaccine: 20% lower dementia in 7-yr study, Eyting 2024 Nature). | G20: Vaccine record, due dates | H20: Live vaccines contraindicated in immunocompromise. | I20: CDC-VAX · EYTING-2024 | J20: Primary Care / Pharmacy
A21: Cognitive + social | B21: Brain/longevity | C21: Daily + weekly | D21: Daily: 30–60 min effortful learning (language, instrument, complex skill). Weekly: ≥2 in-person social contacts + 1 deep conversation. Hearing aids if any loss (Lancet 2024). | E21: 12 of 14 Lancet 2024 dementia risk factors managed | F21: Lancet 2024 Dementia Commission: 14 modifiable risk factors = 45% attributable dementia risk. Hearing loss = #1 modifiable. Social isolation is independent risk factor as strong as smoking 15 cigarettes/day (Holt-Lunstad 2010). | G21: Cognitive activity log, social contact count, hearing test, vision check | H21: Memory decline or depression → primary care for workup. | I21: NIA-COG · LANCET-2024 · HOLT-LUNSTAD-2010 | J21: Self / Family / Clinician
A22: Recovery & deload | B22: Recovery | C22: Continuous | D22: Adjust training by pain, sleep, fatigue, resting pulse, mood. 1 low-load day/week (Sunday). Deload week every 4–8 weeks if needed. | E22: Train to improve over weeks, not deplete | F22: Adaptation requires recovery (supercompensation). Chronic overtraining = elevated cortisol, suppressed HRV, plateaus, injury. | G22: Resting HR trend, HRV (if measured), perceived fatigue | H22: Resting HR > +5 bpm above baseline for ≥3 days → deload. | I22: CDC-ACT | J22: Self / Trainer

Sheet 05_30Day_Rotation
A1: 30-Day Onboarding Rotation — Upper Back + Core First | K1: Created | L1: 2026-05-15 11:11 PM CT
A2: Every strength session begins with warm-up, upper-back activation, and core bracing before legs/push/cardio. Week 1 is deliberately easy; Week 2 progresses gently; Weeks 3–4 expand whole-body capacity.
A4: Day | B4: Week | C4: Type | D4: Warm-up | E4: Priority block: upper back + core | F4: Secondary block | G4: Cardio / steps | H4: Cool-down | I4: Nutrition focus | J4: Intensity cap | K4: Milestone / notes | L4: Source key
A5: 1 | B5: 1 | C5: Foundation strength | D5: 8 min easy walk + cat-cow + shoulder circles | E5: Band row 2×10; dead bug 2×6/side; wall slide 1×8 | F5: Sit-to-stand 2×8; glute bridge 2×8 | G5: 10–15 min easy walk | H5: 5 min slow breathing + thoracic rotation | I5: Protein breakfast + fiber | J5: RPE 5–6 | K5: Learn form; finish feeling better than start | L5: CDC-ACT
A6: 2 | B6: 1 | C6: Zone 2 + mobility | D6: 8 min easy walk | E6: Band pull-apart 2×12; bird dog 2×6/side | F6: Hip hinge drill 2×8 | G6: 20–25 min brisk walk/cycle conversational | H6: Hamstring/hip flexor stretch 5 min | I6: Hydration + plants at lunch | J6: RPE 4–5 | K6: Easy aerobic base | L6: CDC-ACT
A7: 3 | B7: 1 | C7: Foundation strength | D7: 8 min warm-up + band external rotation | E7: Face pull 2×12; side plank 2×15 sec/side | F7: Incline push-up 2×8; suitcase carry 2×30 sec | G7: 10 min easy walk | H7: Child's pose breathing + pec stretch | I7: Protein per meal | J7: RPE 5–6 | K7: Core stiffness without strain | L7: NIA-STRENGTH
A8: 4 | B8: 1 | C8: Recovery mobility | D8: Joint circles + nasal walk | E8: Wall slide 2×8; dead bug 1×6/side | F8: Tandem stance 3×20 sec; calf raise 2×10 | G8: 20 min easy walk | H8: Long exhale breathing | I8: Omega-3 fish/plant fats | J8: RPE 3–4 | K8: Let connective tissue adapt | L8: USPSTF-FALLS
A9: 5 | B9: 1 | C9: Foundation strength | D9: 8 min easy walk + t-spine opener | E9: Band row 2×12; bird dog 2×8/side; face pull 1×12 | F9: Goblet box squat 2×8 light; farmer carry 2×30 sec | G9: Optional easy bike 10–15 min | H9: 5–8 min mobility | I9: Fiber target | J9: RPE 5–6 | K9: End Week 1 with no soreness spike | L9: CDC-ACT
A10: 6 | B10: 1 | C10: Long easy cardio | D10: 10 min walk warm-up | E10: Band pull-apart 2×12; side plank 2×15 sec/side | F10: Mobility flow 10 min | G10: 30–45 min easy walk/hike/cycle | H10: Calves/hips/t-spine 8 min | I10: Mediterranean meal prep | J10: RPE 4–5 | K10: Keep it social and easy | L10: CDC-ACT
A11: 7 | B11: 1 | C11: Full recovery | D11: 5 min gentle walk | E11: Posture reset: wall slide 1×8; dead bug 1×6/side | F11: Balance 3 min supported | G11: Optional leisure walk | H11: Warm shower + breathing | I11: Plan groceries | J11: RPE 2–3 | K11: Review what felt easy/hard | L11: CDC-ACT
A12: 8 | B12: 2 | C12: Progress strength | D12: 10 min warm-up | E12: Band row 3×10; dead bug 3×6/side; wall slide 2×8 | F12: Sit-to-stand 3×8; glute bridge 3×8 | G12: 15 min easy walk | H12: 5–8 min cool-down | I12: Protein + leucine at breakfast | J12: RPE 6–7 | K12: +1 set vs Week 1 | L12: NIA-STRENGTH
A13: 9 | B13: 2 | C13: Zone 2 + balance | D13: 8–10 min warm-up | E13: Face pull 2×12; bird dog 3×6/side | F13: Step-up 2×8/side; calf raise 2×12 | G13: 25–35 min Zone 2 | H13: Hip flexor/t-spine 8 min | I13: Color count 5+ | J13: RPE 5–6 | K13: Increase cardio slightly | L13: CDC-ACT
A14: 10 | B14: 2 | C14: Upper/core emphasis | D14: 10 min warm-up | E14: Single-arm row 3×10/side; side plank 3×20 sec; band pull-apart 2×15 | F14: Incline push-up 3×8; suitcase carry 3×30 sec | G14: 10–15 min easy walk | H14: Pec/lat stretch + breathing | I14: Fiber 30g target if tolerated | J14: RPE 6–7 | K14: Posture + anti-rotation | L14: NIA-STRENGTH
A15: 11 | B15: 2 | C15: Recovery mobility | D15: 8 min nasal walk | E15: Wall slide 2×10; dead bug 2×8/side | F15: Tandem walk 3×10 steps; hip hinge drill 2×10 | G15: 25 min easy walk | H15: Long exhale breathing | I15: Hydration target | J15: RPE 3–4 | K15: Active recovery | L15: USPSTF-FALLS
A16: 12 | B16: 2 | C16: Whole-body intro | D16: 10 min warm-up | E16: Band row 3×12; face pull 2×12; bird dog 2×8/side | F16: Goblet squat 3×8; RDL light 2×8; farmer carry 3×30 sec | G16: Optional easy bike 15 min | H16: 5–8 min mobility | I16: Protein at each meal | J16: RPE 6–7 | K16: Small load increase only if pain-free | L16: CDC-ACT
... A34: 30 | B34: 4 | C34: Zone 2 | D34: 10 min warm-up | E34: Band pull-apart 2×15; bird dog 2×8/side | F34: Mobility 8–10 min | G34: 30–60 min aerobic depending on day | H34: 5–10 min cool-down | I34: Keep protein/fiber/hydration consistent | J34: RPE 5–6 | K34: Expand only if sleep/pain/readiness are good | L34: CDC-ACT

Sheet 06_Weekly_Plan
A1: Weekly Plan — Progression Built Around Upper Back + Core | K1: Created | L1: 2026-05-15 11:11 PM CT
A2: Use this after onboarding or anytime you restart. The first strength priority is upper back + core bracing; legs, push, cardio, and power expand after form is clean and pain-free.
A4: Day | B4: Focus | C4: Warm-up | D4: Priority first: upper back + core | E4: Then train | F4: Cool-down | G4: Week 1 easy version | H4: Week 2 progression | I4: Do not progress if | J4: Target | K4: Source key | L4: Notes
A5: Monday | B5: Strength A — posture/core + lower | C5: 8–10 min walk + cat-cow + shoulder circles | D5: Band row + dead bug + wall slide | E5: Sit-to-stand/goblet squat + glute bridge + farmer carry | F5: 5–10 min walk + t-spine/hip flexor stretch | G5: 2 sets each, RPE 5–6 | H5: 3 sets or +5–10% load, RPE 6–7 | I5: Pain >3/10, poor sleep, form breaks | J5: 35–45 min | K5: CDC-ACT | L5: Upper back/core always first
A6: Tuesday | B6: Zone 2 + mobility | C6: 5–8 min easy walk | D6: Band pull-apart + bird dog | E6: Zone 2 walk/bike + ankle/hip mobility | F6: Breathing 3–5 min | G6: 20–30 min Z2 | H6: 30–40 min Z2 | I6: Cannot nasal/talk comfortably | J6: Conversational pace | K6: CDC-ACT | L6: Build aerobic base
A7: Wednesday | B7: Strength B — upper/core + push | C7: 8–10 min warm-up + band external rotation | D7: Face pull + side plank + thoracic rotation | E7: Incline push-up + assisted pull/lat pulldown + suitcase carry | F7: Pec/lat stretch + breathing | G7: 2 sets each, RPE 5–6 | H7: 3 sets or harder incline/band, RPE 6–7 | I7: Shoulder/back pain, shrugging, breath-holding | J7: 35–45 min | K7: NIA-STRENGTH | L7: Keep shoulders down/back
A8: Thursday | B8: Recovery + balance | C8: Gentle walk + joint circles | D8: Wall slide + dead bug light | E8: Tandem stance/walk + supported single-leg + mobility | F8: Long exhale breathing | G8: 20–30 min easy | H8: 30–40 min easy or add balance time | I8: Dizziness or unsteady gait | J8: Low intensity | K8: USPSTF-FALLS | L8: Safety support nearby
A9: Friday | B9: Strength C — whole body | C9: 8–10 min walk + hinge drill | D9: Row + bird dog + anti-rotation carry | E9: Goblet squat + RDL + incline push-up + calf raise | F9: Hips/t-spine/calf stretch | G9: 2 sets each, RPE 5–6 | H9: 3 sets; add small load if pain-free | I9: Back rounding or grip fatigue alters posture | J9: 40–50 min | K9: CDC-ACT | L9: Practice bracing before hinge
A10: Saturday | B10: Long Zone 2 / outdoor | C10: 10 min easy ramp-up | D10: Band pull-apart + side plank short | E10: Long walk/hike/bike/swim | F10: Mobility 8–10 min | G10: 30–45 min | H10: 45–60 min | I10: Lingering soreness or unusual fatigue | J10: Easy-moderate | K10: CDC-ACT | L10: Social/outdoor is ideal
A11: Sunday | B11: Recovery review | C11: 5 min gentle walk | D11: Posture reset 1–2 rounds | E11: Mobility/yoga + weekly review | F11: Warm bath / breathing | G11: 20–30 min | H11: Same; do not chase fatigue | I11: Any red flag pain | J11: Low intensity | K11: CDC-ACT | L11: Plan next week
A13: WEEKLY VOLUME TRACKER
A14: Domain | B14: Target | C14: This week | D14: % of target | E14: Status | F14: Progression rule
A15: Upper-back sessions | B15: 3 | C15: 0 | D15: =IFERROR(C15/B15,0) -> 0 | E15: =IF(D15>=1,"Complete",IF(D15>=0.7,"On track","Needs attention")) -> Needs attention | F15: If 3/3 sessions pain-free, add 1 set or stronger band next week
A16: Core/bracing sessions | B16: 3 | C16: 0 | D16: =IFERROR(C16/B16,0) -> 0 | E16: =IF(D16>=1,"Complete",IF(D16>=0.7,"On track","Needs attention")) -> Needs attention | F16: If bracing remains clean, add 5–10 sec or 1 set
A17: Strength sessions | B17: 3 | C17: 0 | D17: =IFERROR(C17/B17,0) -> 0 | E17: =IF(D17>=1,"Complete",IF(D17>=0.7,"On track","Needs attention")) -> Needs attention | F17: Progress only one variable: sets OR load OR reps
A18: Zone 2 minutes | B18: 150 | C18: 0 | D18: =IFERROR(C18/B18,0) -> 0 | E18: =IF(D18>=1,"Complete",IF(D18>=0.7,"On track","Needs attention")) -> Needs attention | F18: Add 10–15 min/week until target is easy
A19: Balance days | B19: 5 | C19: 0 | D19: =IFERROR(C19/B19,0) -> 0 | E19: =IF(D19>=1,"Complete",IF(D19>=0.7,"On track","Needs attention")) -> Needs attention | F19: Add time before reducing hand support
A20: Warm-up/cool-down compliance | B20: 6 | C20: 0 | D20: =IFERROR(C20/B20,0) -> 0 | E20: =IF(D20>=1,"Complete",IF(D20>=0.7,"On track","Needs attention")) -> Needs attention | F20: No warm-up = no progression

Sheet 07_Exercise_Library
A1: Exercise Library — Upper Back + Core First Progression | K1: Created | L1: 2026-05-15 11:11 PM CT
A2: Use this as the clickable reference layer. Start every strength day with priority 1 items. Video links are YouTube search links, not medical prescriptions.
A4: Priority | B4: Category | C4: Exercise | D4: How to do it | E4: Week 1 dosage | F4: Week 2 progression | G4: Why | H4: Key cue | I4: Safety | J4: Video link | K4: Source key | L4: Notes
A5: 1 | B5: Warm-up | C5: Nasal breathing walk | D5: Walk at easy pace through the nose; gradually increase arm swing. | E5: 5 min | F5: 6–8 min | G5: Raises temperature and shifts from rest to training without strain. | H5: You can talk in full sentences. | I5: Stop if chest pain/dizziness. | J5: https://www.youtube.com/results?search_query=nasal+breathing+warm+up+walk+exercise+older+adults | K5: CDC-ACT | L5: Do before every session
A6: 1 | B6: Warm-up | C6: Cat-cow + thoracic rotation | D6: On hands/knees, alternate spinal flex/extend; then thread needle rotation. | E6: 1–2 min | F6: 2–3 min | G6: Prepares spine and rib cage for bracing and shoulder motion. | H6: Move slowly with breath. | I6: Avoid painful end range. | J6: https://www.youtube.com/results?search_query=cat+cow+thoracic+rotation+warm+up | K6: CDC-ACT
A7: 1 | B7: Upper back | C7: Band row | D7: Anchor band at chest height, pull elbows back, squeeze shoulder blades, control return. | E7: 2×10 easy | F7: 3×10–12 or stronger band | G7: Builds scapular retraction for posture and shoulder health. | H7: Elbows close; neck long. | I7: Secure anchor; no low-back lean. | J7: https://www.youtube.com/results?search_query=resistance+band+row+proper+form | K7: NIA-STRENGTH | L7: Starting-point exercise
A8: 1 | B8: Upper back | C8: Band face pull | D8: Anchor band high, pull toward nose/forehead with elbows high, rotate thumbs back. | E8: 2×12 easy | F8: 3×12–15 | G8: Targets rear delts/external rotators to balance rounded posture. | H8: Pull to face, not chest. | I8: Use light band; no shoulder pinch. | J8: https://www.youtube.com/results?search_query=band+face+pull+proper+form | K8: NIA-STRENGTH
A9: 1 | B9: Upper back | C9: Wall slide | D9: Back/forearms against wall if possible, slide arms overhead without rib flare. | E9: 1–2×8 | F9: 2–3×8–10 | G9: Improves shoulder flexion and thoracic posture before overhead work. | H9: Ribs down; chin tucked. | I9: Do floor version if shoulder discomfort. | J9: https://www.youtube.com/results?search_query=wall+slide+exercise+proper+form | K9: NIA-STRENGTH
A10: 1 | B10: Core | C10: Dead bug | D10: Lie on back, brace gently, extend opposite arm/leg while low back stays heavy. | E10: 2×6/side | F10: 3×6–8/side or slower tempo | G10: Trains anti-extension core control that protects spine during lifting. | H10: Exhale as limb extends. | I10: Stop if back arches or hurts. | J10: https://www.youtube.com/results?search_query=dead+bug+exercise+proper+form | K10: NIA-STRENGTH | L10: Starting-point core
A11: 1 | B11: Core | C11: Bird dog | D11: Hands/knees, extend opposite arm/leg; pause without hip rotation. | E11: 2×6/side | F11: 3×6–8/side with 2-sec hold | G11: Builds spinal stability and glute/core coordination. | H11: Hips stay square. | I11: Use short range if back pain. | J11: https://www.youtube.com/results?search_query=bird+dog+exercise+proper+form | K11: NIA-STRENGTH
A12: 1 | B12: Core | C12: Side plank from knees | D12: Side-lying, knees bent, lift hips, keep straight line shoulder-hip-knee. | E12: 2×15 sec/side | F12: 3×20–25 sec/side | G12: Trains lateral core and hip stability for gait and back protection. | H12: Push floor away. | I12: Stop if shoulder pain. | J12: https://www.youtube.com/results?search_query=side+plank+from+knees+proper+form | K12: NIA-STRENGTH
A13: 2 | B13: Lower body | C13: Sit-to-stand | D13: Stand from chair, sit back down slowly without dropping. | E13: 2×8 | F13: 3×8–10 or lower chair | G13: Foundational lower-body strength; transfers to daily life and fall resilience. | H13: Knees track toes. | I13: Use hands/support if needed. | J13: https://www.youtube.com/results?search_query=sit+to+stand+exercise+older+adults+proper+form | K13: CDC-ACT
A14: 2 | B14: Lower body | C14: Glute bridge | D14: Lie on back, knees bent, squeeze glutes and lift hips without arching back. | E14: 2×8 | F14: 3×8–12 or 2-sec hold | G14: Builds hips/posterior chain with low spine load. | H14: Ribs down; squeeze glutes. | I14: Avoid lumbar arching. | J14: https://www.youtube.com/results?search_query=glute+bridge+proper+form+older+adults | K14: CDC-ACT
A15: 2 | B15: Lower body | C15: Goblet box squat | D15: Hold light DB at chest, squat to box/chair, stand tall. | E15: 2×8 light | F15: 3×8 or +5% load if pain-free | G15: Adds loaded squat pattern after bracing is learned. | H15: Brace before descent. | I15: No knee collapse; pain-free depth. | J15: https://www.youtube.com/results?search_query=goblet+squat+to+box+proper+form | K15: CDC-ACT
A16: 2 | B16: Hinge | C16: Dumbbell Romanian deadlift | D16: Soft knees, hips back, weights close to thighs, stand by driving hips forward. | E16: 2×8 light after Week 1 | F16: 3×8 light/moderate | G16: Posterior chain strength supports gait, back resilience, and power. | H16: Hips back, spine long. | I16: Stop for back pain/form loss. | J16: https://www.youtube.com/results?search_query=dumbbell+Romanian+deadlift+proper+form | K16: CDC-ACT
A17: 2 | B17: Push | C17: Incline push-up | D17: Hands on wall/counter/bench, straight line body, lower chest under control. | E17: 2×8 | F17: 3×8–12 or lower incline | G17: Trains push strength with scalable joint stress. | H17: Elbows ~45°; shoulders down. | I17: Avoid shoulder pinch. | J17: https://www.youtube.com/results?search_query=incline+push+up+proper+form+older+adults | K17: CDC-ACT
A18: 2 | B18: Carry/grip | C18: Farmer carry | D18: Hold DBs at sides, walk slowly tall with ribs stacked over hips. | E18: 2×30 sec | F18: 3×30–40 sec or heavier | G18: Builds grip, trunk stiffness, posture, and gait confidence. | H18: Walk tall; quiet steps. | I18: Clear path; set down safely. | J18: https://www.youtube.com/results?search_query=farmer+carry+proper+form | K18: NIA-STRENGTH
A19: 2 | B19: Balance | C19: Tandem stance / walk | D19: Stand heel-to-toe near support; progress to slow heel-to-toe steps. | E19: 3×20 sec | F19: 3×30 sec or less hand support | G19: Balance training reduces fall risk when practiced consistently. | H19: Light fingertip support is OK. | I19: Do near counter/wall. | J19: https://www.youtube.com/results?search_query=tandem+stance+balance+exercise+older+adults | K19: USPSTF-FALLS
A20: 3 | B20: Cool-down | C20: Slow walk + long exhale breathing | D20: Walk slowly, then breathe in 3–4 sec and out 5–8 sec. | E20: 3–5 min | F20: 5–8 min | G20: Downshifts arousal and helps recovery after training. | H20: Longer exhale than inhale. | I20: Sit if lightheaded. | J20: https://www.youtube.com/results?search_query=cool+down+breathing+after+exercise | K20: CDC-ACT
A21: 3 | B21: Cool-down | C21: Hip flexor + pec doorway stretch | D21: Half-kneel hip flexor stretch; doorway pec stretch, gentle only. | E21: 30 sec/side each | F21: 45–60 sec/side | G21: Offsets sitting posture and training tension. | H21: Mild stretch, not pain. | I21: Avoid aggressive stretching after hard sessions. | J21: https://www.youtube.com/results?search_query=hip+flexor+pec+doorway+stretch+proper+form | K21: CDC-ACT

Sheet 08_Nutrition
A1: Nutrition Plan — Food-First Mediterranean for Healthy Aging After 60 | K1: Created | L1: 2026-05-15 11:11 PM CT
A2: Whole-food first. Targets pull live from 01_Personal_Settings. Supplements only when food cannot deliver.
A4: ="Daily targets: " & '01_Personal_Settings'!B19 & " g protein · " & '01_Personal_Settings'!B21 & " L water · " & ROUND('01_Personal_Settings'!B20,0) & " g protein/meal (leucine threshold)" -> Daily targets: 94 g protein · 1.8 L water · 24 g protein/meal (leucine threshold)
A6: CORE TARGETS
A7: Pillar | B7: Target | C7: How | D7: Examples | E7: Why | F7: Frequency | G7: Track | H7: Source key | I7: Notes
A8: Protein (active aging) | B8: =" "&'01_Personal_Settings'!B19&" g/day = ~1.6 g/kg" -> 94 g/day = ~1.6 g/kg | C8: Split across 4 meals · 2.5 g leucine/meal | D8: Greek yogurt · eggs · salmon · chicken · tofu · lentils · whey/casein | E8: Reverses sarcopenia; supports training adaptation | F8: Daily | G8: g per meal | H8: PROT-AGE · MORTON-2018 | I8: Kidney disease (eGFR <60): nephrologist plan, usually 0.6–0.8 g/kg
A9: Vegetables + fruit | B9: 5+ colors/day, ≥400 g | C9: Half plate at lunch + dinner | D9: Greens · berries · cruciferous · tomatoes · peppers · sweet potato | E9: Polyphenols, fiber, micronutrients drive cardiometabolic health | F9: Every meal | G9: Colors/day | H9: DGA-2025 | I9: Frozen is fine; canned watch sodium
A10: Whole grains + legumes | B10: 3–6 servings/day | C10: Replace refined grains | D10: Oats · lentils · chickpeas · black beans · quinoa · barley · whole-wheat bread | E10: Fiber, B vitamins, slow-release glucose; PURE study link to lower mortality | F10: Daily | G10: Servings | H10: DGA-2025 · PURE-2017 | I10: Soak/sprout if GI sensitive
A11: Healthy fats | B11: 2–4 servings/day | C11: Olive oil base; nuts/seeds; fatty fish 2×/wk | D11: EVOO · walnuts · almonds · chia · flax · salmon · sardines | E11: Mediterranean pattern → 30% lower cardiac events (PREDIMED) | F11: Daily | G11: Tbsp olive oil | H11: PREDIMED-2018 | I11: Use EVOO for cooking (smoke point 410°F)
A12: Fiber | B12: 30–40 g/day | C12: Soluble + insoluble; ramp up slowly | D12: Legumes · oats · berries · chia · psyllium if gap | E12: Lipids, glucose, satiety, gut microbiome | F12: Daily | G12: g/day | H12: DGA-2025 | I12: Start low, increase weekly to avoid GI distress
A13: Hydration | B13: =" "&'01_Personal_Settings'!B21&" L/day" -> 1.8 L/day | C13: 30 mL/kg/day; more with sauna/exercise | D13: Water · unsweetened tea · mineral water · electrolytes if needed | E13: Cognitive function, BP regulation, kidney health | F13: Daily | G13: Urine color | H13: NAM-2005 | I13: Heart/kidney patients: clinician-set limit overrides
A14: Alcohol | B14: None or minimal | C14: Never as sleep aid; small amounts only if used | D14: Alcohol-free dinner default | E14: Disrupts sleep, increases BP, falls, liver risk, cancer | F14: Ongoing | G14: Drinks/wk | H14: DGA-2025 | I14: Discuss with clinician if hard to reduce
A17: MEAL BUILDERS
A18: Meal | B18: Formula | C18: Sample 1 | D18: Sample 2 | E18: Sample 3 | F18: Protein hit? | G18: Walk after? | H18: Source key | I18: Notes
A19: Breakfast | B19: 1 protein + 1 fiber-carb + 1 colorful plant + 1 fat | C19: Greek yogurt + berries + walnuts + chia | D19: 3-egg omelet + spinach + whole-grain toast + avocado | E19: Tofu scramble + black beans + salsa + olive oil | F19: ="~"&'01_Personal_Settings'!B20&" g" -> ~24 g | G19: No | H19: PROT-AGE · DGA-2025 | I19: Adjust portions to weight goal
A20: Lunch | B20: Protein bowl: protein + 2 vegetables + 1 legume/grain + olive oil | C20: Salmon + greens + chickpeas + EVOO | D20: Chicken + quinoa + roasted veg + tahini | E20: Dal + brown rice + cucumber-tomato salad | F20: ="~"&'01_Personal_Settings'!B20&" g" -> ~24 g | G20: 10-min walk | H20: DGA-2025 | I20: Largest plant-forward meal
A21: Dinner | B21: Lighter protein + vegetables; finish 2–3 hr before bed | C21: Baked fish + roasted vegetables + lemon | D21: Lentil soup + side salad + olive oil | E21: Tofu/paneer + greens + brown rice | F21: ="~"&'01_Personal_Settings'!B20&" g" -> ~24 g | G21: Optional 10 min | H21: DGA-2025 · CDC-SLEEP | I21: Heavy/late = worse sleep
A22: Snacks (if needed) | B22: Protein + fiber pair | C22: Greek yogurt + berries | D22: Apple + almond butter | E22: Hummus + carrots | F22: ~15 g protein | G22: No | H22: PROT-AGE | I22: Only if protein gap or training day
A25: HIGH-PROTEIN FOODS REFERENCE
A26: Food | B26: Serving | C26: Protein (g) | D26: Leucine (g) | E26: Hits per-meal target? | F26: Notes
A27: Salmon (cooked) | B27: 4 oz / 113 g | C27: 25 | D27: 2 | E27: =IF(C27>='01_Personal_Settings'!$B$20,"✓ Yes",IF(C27>='01_Personal_Settings'!$B$20*0.6,"Partial","No")) -> ✓ Yes | F27: Plus omega-3
A28: Chicken breast | B28: 4 oz / 113 g | C28: 30 | D28: 2.4 | E28: =IF(C28>='01_Personal_Settings'!$B$20,"✓ Yes",IF(C28>='01_Personal_Settings'!$B$20*0.6,"Partial","No")) -> ✓ Yes | F28: Lean, versatile
A29: Greek yogurt (plain, non-fat) | B29: 1 cup / 245 g | C29: 23 | D29: 2.4 | E29: =IF(C29>='01_Personal_Settings'!$B$20,"✓ Yes",IF(C29>='01_Personal_Settings'!$B$20*0.6,"Partial","No")) -> Partial | F29: Pre-bed option
A30: Eggs | B30: 3 large | C30: 18 | D30: 1.5 | E30: =IF(C30>='01_Personal_Settings'!$B$20,"✓ Yes",IF(C30>='01_Personal_Settings'!$B$20*0.6,"Partial","No")) -> Partial | F30: Pair with another protein
A31: Cottage cheese (low-fat) | B31: 1 cup | C31: 28 | D31: 2.8 | E31: =IF(C31>='01_Personal_Settings'!$B$20,"✓ Yes",IF(C31>='01_Personal_Settings'!$B$20*0.6,"Partial","No")) -> ✓ Yes | F31: Highest leucine/calorie
A32: Lentils (cooked) | B32: 1 cup | C32: 18 | D32: 1.4 | E32: =IF(C32>='01_Personal_Settings'!$B$20,"✓ Yes",IF(C32>='01_Personal_Settings'!$B$20*0.6,"Partial","No")) -> Partial | F32: Add quinoa or whey for full profile
A33: Tofu (firm) | B33: 4 oz / 113 g | C33: 20 | D33: 1.5 | E33: =IF(C33>='01_Personal_Settings'!$B$20,"✓ Yes",IF(C33>='01_Personal_Settings'!$B$20*0.6,"Partial","No")) -> Partial | F33: Complete protein
A34: Whey protein | B34: 1 scoop / 30 g | C34: 25 | D34: 2.7 | E34: =IF(C34>='01_Personal_Settings'!$B$20,"✓ Yes",IF(C34>='01_Personal_Settings'!$B$20*0.6,"Partial","No")) -> ✓ Yes | F34: Fastest leucine spike
A35: Canned tuna | B35: 1 can / 5 oz | C35: 30 | D35: 2.4 | E35: =IF(C35>='01_Personal_Settings'!$B$20,"✓ Yes",IF(C35>='01_Personal_Settings'!$B$20*0.6,"Partial","No")) -> ✓ Yes | F35: Cheap, shelf-stable
A36: Almonds | B36: 1 oz / 28 g | C36: 6 | D36: 0.4 | E36: =IF(C36>='01_Personal_Settings'!$B$20,"✓ Yes",IF(C36>='01_Personal_Settings'!$B$20*0.6,"Partial","No")) -> No | F36: Snack, not meal protein
A39: 🚨 NUTRITION RED FLAGS — see clinician
A40: Unintentional weight loss · swallowing difficulty · anemia symptoms (fatigue, pallor) · GI bleeding · severe constipation · recurring hypoglycemia · unexplained appetite change. Do not self-treat with supplements — may signal underlying disease.
A42: TRAINING-DAY NUTRITION ADDITIONS — SUPPORT UPPER BACK/CORE START
A43: Situation | B43: Do this | C43: Timing | D43: Why | E43: Week 1 | F43: Week 2+ | G43: Caution | H43: Source key
A44: Morning strength day | B44: Protein + fluid before/after training; avoid training dehydrated | C44: Before or breakfast after | D44: Supports muscle protein synthesis and reduces fatigue | E44: Keep simple: yogurt/eggs/whey/tofu + fruit | F44: Add carbs if sessions exceed 45 min | G44: Kidney disease/diabetes: clinician plan | H44: PROT-AGE
A45: Upper-back/core progression | B45: Aim for protein at each meal, not just dinner | C45: 3–4 feedings/day | D45: Older adults may need a stronger per-meal protein stimulus | E45: 20–35g/meal depending body size | F45: Keep consistent | G45: Use body-weight target from settings | H45: PROT-AGE
A46: Zone 2 days | B46: Carbs from whole grains/fruit/legumes around activity if energy is low | C46: Meal before/after | D46: Improves adherence and reduces compensation hunger | E46: Normal meals are enough | F46: Add portion if duration rises | G46: Glucose issues: monitor response | H46: DGA-2025
A47: Recovery days | B47: Fiber, plants, hydration, omega-3-rich foods | C47: All day | D47: Supports cardiometabolic health and inflammation balance | E47: No diet restriction extremes | F47: Same | G47: Avoid supplement megadoses | H47: DGA-2025

Sheet 09_Supplements
A1: Supplements — Decision Framework with Stop Rules | K1: Created | L1: 2026-05-15 11:11 PM CT
A2: Every supplement has: reason · dose · trigger marker · skip-if · stop rule · interaction check. No orphan bottles.
A4: CATEGORY: A = replacement (skip if normal) · B = therapeutic dose (take regardless of labs) · C = optional/cycle
A5: STATUS: Active = take it · Discuss = needs clinician sign-off · Caution = take only if needed · Avoid = do not start without specialist · Deprioritize = evidence too thin
A6: EVIDENCE: GREEN = strong RCT/meta · YELLOW = moderate · RED = speculative
A8: Supplement | B8: Cat. | C8: Status | D8: Dose | E8: Frequency | F8: Timing / food | G8: Trigger marker | H8: Skip if | I8: Stop rule | J8: Do NOT combine with | K8: Why (mechanism) | L8: Evidence | M8: Source key
A9: Creatine monohydrate | B9: B | C9: Active | D9: 5 g | E9: DAILY (no exceptions) | F9: Any time · with food fine | G9: N/A — no blood marker | H9: Never skip (saturation effect) | I9: Stop if kidney disease develops; otherwise lifelong | J9: Nothing major. Caffeine concern overstated. | K9: Muscle/brain saturation; ATP regeneration. ~28 days to fill pool. Strength, lean mass, cognition. | L9: STRONG | M9: KREIDER-2017
A10: Omega-3 (EPA+DHA) | B10: B | C10: Active | D10: 2 g EPA+DHA combined | E10: DAILY (EOD acceptable at ≥3 g) | F10: AM with breakfast (fat required) | G10: Omega-3 index (RBC) | H10: ≥8% omega-3 index → 1 g maintenance | I10: Stop 7 days before surgery; reassess if bleeding events | J10: Zinc (separate 2h). Anticoagulants — consult MD. | K10: Cell membrane phospholipid incorporation; anti-inflammatory eicosanoids. Half-life ~30h. | L10: STRONG | M10: HARRIS-2017 · MASON-2022
A11: Psyllium husk fiber | B11: B | C11: Active | D11: 5–10 g | E11: DAILY | F11: Any meal · 250 mL water | G11: LDL-C, ApoB | H11: Continue regardless — daily fiber goal | I11: Stop only if confirmed obstruction; otherwise lifelong | J11: ⚠️ ALL medications + supplements — bind 2h apart | K11: Bile-acid sequestration → ~7% LDL drop. Glucose smoothing. Microbiome substrate. | L11: STRONG | M11: BRUM-2018
A12: Curcumin + piperine (or phytosomal) | B12: B | C12: Active | D12: 500–1000 mg | E12: ALTERNATE DAY acceptable | F12: PM with fat | G12: hs-CRP (anti-inflammation target) | H12: hs-CRP <0.5 → continue at low dose if goal is met | I12: Stop if abnormal LFTs (rare hepatotoxicity reports) | J12: Anticoagulants. Iron (chelation). | K12: NF-κB inhibition; tissue anti-inflammatory effect. Long retention supports EOD. | L12: MODERATE | M12: DAILY-2016
A13: Vitamin D3 + K2 (MK-7) | B13: A | C13: Discuss | D13: 2000–4000 IU D3 + 100 mcg MK-7 | E13: DAILY (or 10,000 IU 2×/wk EOD) | F13: AM · with fat | G13: 25(OH)D vitamin D | H13: ≥60 ng/mL → 1000 IU maintenance | I13: Re-test 8 wks after starting; stop if calcium rises | J13: K2 + warfarin — consult MD. Otherwise nothing. | K13: Northern latitude (Minnesota) = limited UVB Oct–Apr. "Normal" 30 ng/mL is below longevity-optimal. | L13: STRONG | M13: MANSSON-2024 · NIH-ODS-D
A14: Vitamin B12 (methylcobalamin) | B14: A | C14: Discuss | D14: 500–1000 mcg | E14: EOD or 2×/wk if normal | F14: AM · either | G14: Serum B12 + MMA | H14: B12 >500 AND MMA <0.4 → maintenance only | I14: Stop full dose when MMA normalizes | J14: Nothing. | K14: Stomach acid drops with age → absorption falls. Liver stores ~2 yr of B12. | L14: STRONG (if 60+) | M14: USPSTF-B12 · LINDENBAUM-1994
A15: Magnesium glycinate or threonate | B15: A/C | C15: Active | D15: 200–400 mg elemental | E15: DAILY (split AM/PM or PM only) | F15: PM 1h pre-bed | G15: RBC magnesium (serum unreliable) | H15: RBC Mg >5.5 mg/dL — most adults subclinically low | I15: Stop if diarrhea persists (switch form) | J15: Calcium (separate 2h). High zinc. | K15: Glycinate = sleep/anxiolytic (NMDA). Threonate = cognition (CNS penetration). | L15: MODERATE | M15: BOYLE-2017 · SLUTSKY-2010
A16: CoQ10 (ubiquinol) | B16: A | C16: Discuss | D16: 100–200 mg | E16: DAILY if on statin · else SKIP | F16: AM · with fat | G16: Only if on statin / HF | H16: Not on statin → optional only | I16: Stop if statin discontinued | J16: Warfarin — INR check. | K16: Statins deplete CoQ10 (mevalonate pathway). Without statin, evidence weak in healthy adults. | L16: MODERATE (statin only) | M16: MORTENSEN-2014
A17: Multivitamin (broad) | B17: A/C | C17: Optional | D17: 1 serving | E17: DAILY (or EOD) | F17: AM · with food | G17: No single marker | H17: Diet excellent + targeted labs normal → optional | I17: Stop if iron content excess (check ferritin) | J17: Iron content + coffee/tea/calcium (separate 2h). | K17: COSMOS-Mind: cognitive benefit even in well-nourished. Small effect, cheap insurance. | L17: MODERATE | M17: BAKER-2023
A18: Whey or casein protein | B18: B | C18: Active (if needed) | D18: 20–30 g | E18: AS NEEDED to hit per-meal leucine | F18: Any meal short on protein | G18: Track diet protein (not blood) | H18: Hitting 1.6 g/kg from food → skip | I18: No stop rule — food tool | J18: Nothing. | K18: Triggers 2.5–3 g leucine threshold for MPS. Casein slower release for pre-bed. | L18: STRONG | M18: MORTON-2018
A19: Zinc | B19: C | C19: Caution | D19: 15 mg | E19: EOD or 5 days/wk (avoid copper depletion) | F19: PM · either | G19: Plasma zinc | H19: >100 µg/dL → skip | I19: Stop if copper symptoms (anemia, neuro) | J19: ⚠️ Omega-3 + calcium + iron + magnesium — separate 2h | K19: Immune, taste, wound healing. Chronic high dose depletes copper. | L19: MODERATE | M19: PRASAD-2014
... A27: Rapamycin / metformin (off-label) | B27: — | C27: Specialist only | D27: Research/specialist only | E27: Per specialist | F27: Per specialist | G27: No approved longevity indication | H27: No FDA longevity approval | I27: Specialist protocol only | J27: Many drug interactions | K27: Active research, not yet practice standard. Side effects + interactions require specialist supervision. | L27: EXPERIMENTAL | M27: PARTRIDGE-2020
A30: STACKING & SPACING RULES
A31: Combination | B31: Rule
A32: Iron + calcium | B32: Separate by 2 hours. Calcium blocks iron absorption ~50%.
A33: Iron + coffee/tea | B33: Separate by 1–2 hours. Tannins chelate iron.
A34: Zinc + copper | B34: Chronic daily zinc >25 mg depletes copper. Use EOD or 5 days/wk; add 1 mg copper if extended.
A35: Zinc + omega-3 | B35: Separate by 2 hours. Compete for absorption (transition metals + fatty acids).
A36: Calcium + magnesium | B36: Separate by 2 hours. Same intestinal transporters.
A37: Calcium dose ceiling | B37: Single dose ≥500 mg saturates absorption. Split larger totals.
A38: Psyllium + ALL | B38: ⚠️ 2-hour gap from ALL meds + supplements. Psyllium binds them in gut.
A39: Fat-soluble vitamins (A, D, E, K) | B39: Take with fat-containing meal. Otherwise absorption drops ~50%.
A40: B vitamins | B40: AM. Can be activating; PM dosing may disrupt sleep.
A41: Magnesium for sleep | B41: 60–90 min pre-bed. Glycinate or threonate (not citrate — laxative).
A42: Thyroid medication (if any) | B42: Empty stomach, 1h before food. 4h gap from calcium, iron, magnesium.
... A45: Anticoagulants | B45: ⚠️ Many supplements interact (omega-3, curcumin, garlic, ginkgo, vitamin E, vitamin K). Pharmacist review essential.
A47: DECISION ALGORITHM (quarterly after labs)
A48: ① Category B? → Take daily regardless of any blood test. (Creatine, Omega-3, Psyllium)
